Workbook

Sheet README
A1: change_log.xlsx - Nhật ký thay đổi dự án ML
A2: Quy ước | B2: Chỉ THÊM dòng (append-only). Không sửa/xóa dòng cũ; muốn đính chính thì thêm dòng mới và điền Liên_quan_Log_ID.
A3: Loại_hành_động | B3: EXPLORE đọc/khám phá | DISCOVER phát hiện mới | CREATE tạo file | MODIFY sửa | FIX sửa lỗi | DELETE xóa | RUN chạy code/lệnh | VERIFY kiểm chứng | DECISION quyết định (thường do người dùng) | NOTE ghi chú
A4: Người_thực_hiện | B4: Ai thực hiện hành động: 'Claude' hoặc tên người dùng/người khác.
A5: Yêu_cầu_bởi | B5: Ai yêu cầu/quyết định hành động (vd tên người dùng).
A6: Mức_độ | B6: Info < Low < Medium < High < Critical.
A7: Trạng_thái | B7: Done | Open | Needs-confirmation | Reverted | Wontfix.
A8: Trước/Sau | B8: Giá trị, dòng code hoặc hash trước và sau khi thay đổi.
A9: Múi_giờ | B9: Mặc định Asia/Ho_Chi_Minh (đổi bằng biến môi trường LOG_TZ).
A10: Experiments | B10: Mỗi thí nghiệm DL một dòng: Exp_ID, config + hash, seed, metric train/val, checkpoint. Test_metric chỉ điền cho mô hình cuối (test set dùng đúng một lần).
A11: Summary | B11: Thống kê bằng công thức; chạy recalc.py sau khi ghi xong để có giá trị cache.

Sheet Change_Log
A1: Log_ID | B1: Ngày (dd/mm/yyyy) | C1: Giờ (hh:mm:ss) | D1: Múi_giờ | E1: Session_ID | F1: Người_thực_hiện | G1: Loại_actor | H1: Yêu_cầu_bởi | I1: Loại_hành_động | J1: Bước_pipeline | K1: Tên_file | L1: Đường_dẫn | M1: Vị_trí (dòng/cell/hàm) | N1: Nội_dung | O1: Lý_do | P1: Trước | Q1: Sau | R1: Mức_độ | S1: Trạng_thái | T1: Cách_kiểm_chứng | U1: Liên_quan_Log_ID | V1: Đường_dẫn_backup | W1: Lệnh_Công_cụ | X1: Ghi_chú
A2: LOG-0001 | B2: 46287 | C2: 0.49134259 | D2: Asia/Ho_Chi_Minh | E2: S-20260922 | F2: Claude | G2: AI | H2: Huỳnh Kiện Khải | I2: CREATE | J2: P0 Khởi tạo | K2: house_price_ml | L2: . | N2: Tạo khung dự án 'house_price_ml' (11 thư mục) + 04_configs/base.yaml, README.md, .gitignore, requirements.txt | O2: Khung thư mục chuẩn của skill dl-project-from-raw-data | R2: Info | S2: Done | W2: scripts/scaffold_project.py
A3: LOG-0002 | B3: 46287 | C3: 0.49134259 | D3: Asia/Ho_Chi_Minh | E3: S-20260922 | F3: Claude | G3: AI | H3: Huỳnh Kiện Khải | I3: CREATE | J3: P1 Nhập dữ liệu | K3: train.csv | L3: 00_raw | N3: Nhập dataset thô vào 00_raw (sao chép 1 file); đặt 1 file ở chế độ chỉ-đọc | O3: Dữ liệu gốc bất biến; mọi xử lý ghi sang 01_data/ | R3: Info | S3: Done | W3: scripts/scaffold_project.py
A4: LOG-0003 | B4: 46287 | C4: 0.4915162 | D4: Asia/Ho_Chi_Minh | E4: S-20260922 | F4: Claude | G4: AI | H4: Huỳnh Kiện Khải | I4: DECISION | J4: P0 Khởi tạo | N4: Mục tiêu: dự đoán SalePrice (hồi quy) từ dữ liệu bảng Ames Housing. Mục đích: đồ án học tập. Mô hình: pipeline ML (scikit-learn/XGBoost), KHÔNG dùng Deep Learning theo yêu cầu người dùng. | O4: Người dùng xác nhận qua câu hỏi P0 | R4: Info | S4: Done
A5: LOG-0004 | B5: 46287 | C5: 0.4915162 | D5: Asia/Ho_Chi_Minh | E5: S-20260922 | F5: Claude | G5: AI | H5: Huỳnh Kiện Khải | I5: DECISION | J5: P0 Khởi tạo | N5: Metric chính: RMSLE (RMSE trên log1p(SalePrice)), chuẩn Kaggle House Prices. Metric phụ: MAE ($), R². | O5: Người dùng chọn RMSLE/log-RMSE | R5: Info | S5: Done
A6: LOG-0005 | B6: 46287 | C6: 0.49152778 | D6: Asia/Ho_Chi_Minh | E6: S-20260922 | F6: Claude | G6: AI | H6: Huỳnh Kiện Khải | I6: DECISION | J6: P0 Khởi tạo | N6: Ràng buộc môi trường: CPU i5-12400F, GPU RTX5060 có sẵn. Vì đây là mô hình ML trên dữ liệu bảng (không DL) nên không cần GPU; dự báo chạy dưới 5 phút trên CPU. | O6: Người dùng cung cấp thông số máy | R6: Info | S6: Done
A7: LOG-0006 | B7: 46287 | C7: 0.49606481 | D7: Asia/Ho_Chi_Minh | E7: S-20260922 | F7: Claude | G7: AI | H7: Huỳnh Kiện Khải | I7: CREATE | J7: P0 Môi trường | K7: requirements.txt | L7: requirements.txt | N7: Pin dependencies cho pipeline ML (không DL): pandas, numpy, scikit-learn, xgboost, matplotlib, joblib, PyYAML, openpyxl | R7: Info | S7: Done | T7: pip install -r requirements.txt trong venv mới -> thành công; import sklearn(1.8.0), xgboost(3.4.1) OK
A8: LOG-0007 | B8: 46287 | C8: 0.49606481 | D8: Asia/Ho_Chi_Minh | E8: S-20260922 | F8: Claude | G8: AI | H8: Huỳnh Kiện Khải | I8: CREATE | J8: P0 Môi trường | K8: setup_env.sh | L8: setup_env.sh | N8: Script tạo venv + cài dependencies (Linux/macOS) | R8: Info | S8: Done | T8: Chạy thử trong sandbox: venv tạo thành công, cài package OK, import test pass
A9: LOG-0008 | B9: 46287 | C9: 0.49607639 | D9: Asia/Ho_Chi_Minh | E9: S-20260922 | F9: Claude | G9: AI | H9: Huỳnh Kiện Khải | I9: CREATE | J9: P0 Môi trường | K9: setup_env.bat | L9: setup_env.bat | N9: Script tạo venv + cài dependencies (Windows) - chưa chạy thử vì sandbox là Linux | R9: Info | S9: Done
A10: LOG-0009 | B10: 46287 | C10: 0.50430556 | D10: Asia/Ho_Chi_Minh | E10: S-20260922 | F10: Claude | G10: AI | H10: Huỳnh Kiện Khải | I10: DECISION | J10: P0 Cập nhật thông tin | N10: Người dùng cung cấp tên thật: Huỳnh Kiện Khải (tên tài khoản trước đó ghi là Kazana). Từ đây về sau dùng tên thật trong các dòng log mới. | O10: Người dùng yêu cầu trước khi vào P1 | R10: Info | S10: Done
A11: LOG-0010 | B11: 46287 | C11: 0.50431713 | D11: Asia/Ho_Chi_Minh | E11: S-20260922 | F11: Claude | G11: AI | H11: Huỳnh Kiện Khải | I11: FIX | J11: P0 Cập nhật thông tin | N11: README.md: bổ sung tên người thực hiện dự án là Huỳnh Kiện Khải | R11: Info | S11: Done
A12: LOG-0011 | B12: 46288 | C12: 0.5469213 | D12: Asia/Ho_Chi_Minh | E12: S-20260923 | F12: Claude | G12: AI | H12: Huỳnh Kiện Khải | I12: RUN | J12: P1 Kiểm toán dữ liệu | N12: Chạy audit_dataset.py trên 00_raw/train.csv (--label-col SalePrice) | R12: Info | S12: Done | X12: 1 file, 0 lỗi hỏng, 0 dòng trùng, 0 nhóm trùng nội dung. 19 cột có missing (PoolQC 1453/1460, MiscFeature 1406, Alley 1369, Fence 1179, FireplaceQu 690...). SalePrice là hồi quy liên tục nên phân bố nhãn trong report chỉ mang tính tham khảo.
A13: LOG-0012 | B13: 46288 | C13: 0.55101852 | D13: Asia/Ho_Chi_Minh | E13: S-20260923 | F13: Claude | G13: AI | H13: Huỳnh Kiện Khải | I13: CREATE | J13: P1 Kiểm toán dữ liệu | K13: audit_dataset.py | L13: 03_src/scripts/audit_dataset.py | N13: Copy script audit_dataset.py (từ skill) vào dự án để người dùng tự chạy lại được, không phụ thuộc môi trường sandbox | R13: Info | S13: Done
A14: LOG-0013 | B14: 46288 | C14: 0.55409722 | D14: Asia/Ho_Chi_Minh | E14: S-20260923 | F14: Claude | G14: AI | H14: Huỳnh Kiện Khải | I14: FIX | J14: P1 Chỉnh định dạng log | N14: Áp dụng font Times New Roman cho toàn bộ file change_log.xlsx (mọi sheet: README, Change_Log, Findings, File_Registry, Experiments, Summary). Không thay đổi nội dung các dòng cũ. | O14: Người dùng yêu cầu dùng font Times New Roman và ghi tiếng Việt đầy đủ có dấu | R14: Info | S14: Done | X14: Các dòng log trước đó (LOG-0001 đến LOG-0012, FND-0001) được ghi không dấu theo quy ước ví dụ của skill; log là append-only nên không sửa nội dung các dòng cũ đó. Từ dòng này trở đi, mọi mô tả mới sẽ dùng tiếng Việt có dấu đầy đủ.
A15: LOG-0014 | B15: 46288 | C15: 0.55618056 | D15: Asia/Ho_Chi_Minh | E15: S-20260923 | F15: Claude | G15: AI | H15: Huỳnh Kiện Khải | I15: FIX | J15: P1 Chỉnh định dạng log | N15: Ngoại lệ: đã chỉnh sửa trực tiếp nội dung các dòng LOG-0003..LOG-0012 và FND-0001 để thêm dấu tiếng Việt đầy đủ (không đổi ý nghĩa/số liệu, chỉ thêm dấu). | O15: Người dùng yêu cầu tường minh: 'chỉ riêng lần này' được sửa lại log vì tiếng Việt không dấu gây khó hiểu, dù quy tắc mặc định của skill là append-only (không sửa dòng cũ). | R15: Info | S15: Done | U15: LOG-0003,LOG-0004,LOG-0005,LOG-0006,LOG-0007,LOG-0008,LOG-0009,LOG-0010,LOG-0011,LOG-0012,FND-0001
A16: LOG-0015 | B16: 46288 | C16: 0.55784722 | D16: Asia/Ho_Chi_Minh | E16: S-20260923 | F16: Claude | G16: AI | H16: Huỳnh Kiện Khải | I16: FIX | J16: P1 Chỉnh định dạng log | N16: Sửa skill dl-project-from-raw-data: SKILL.md và references/log_schema.md bổ sung quy ước bắt buộc ghi log bằng tiếng Việt có dấu đầy đủ; scripts/log_change.py sửa các dòng README_ROWS (Loại_hành_động, Người_thực_hiện, Yêu_cầu_bởi, Múi_giờ) từ không dấu sang có dấu. Đồng thời cập nhật sheet README của change_log.xlsx trong dự án này cho khớp. | O16: Người dùng yêu cầu sửa skill để log luôn ghi tiếng Việt có dấu, áp dụng cho các dự án sau này | R16: Info | S16: Done
A17: LOG-0016 | B17: 46289 | C17: 0.44153935 | D17: Asia/Ho_Chi_Minh | E17: S-20260924 | F17: Claude | G17: AI | H17: Huỳnh Kiện Khải | I17: RUN | J17: P2 Chia train/val/test | N17: Chạy make_splits.py trên 00_raw/train.csv (--id-col Id --label-col SalePrice --val 0.15 --test 0.15 --seed 42 --version v1) | R17: Info | S17: Done | X17: SalePrice là biến liên tục với gần như mọi giá trị là duy nhất nên stratify theo đúng giá trị thất bại (script tự động cảnh báo và chuyển sang chia ngẫu nhiên). Kết quả: train=1022, val=219, test=219 (~70/15/15). Kiểm chứng tự động: PASSED (không Id nào nằm ở >1 split, không nhóm/sha256 xuyên split).
A18: LOG-0017 | B18: 46289 | C18: 0.44165509 | D18: Asia/Ho_Chi_Minh | E18: S-20260924 | F18: Claude | G18: AI | H18: Huỳnh Kiện Khải | I18: CREATE | J18: P2 Chia train/val/test | K18: make_splits.py | L18: 03_src/scripts/make_splits.py | N18: Copy script make_splits.py (từ skill) vào dự án để chạy lại được độc lập | R18: Info | S18: Done
A19: LOG-0018 | B19: 46289 | C19: 0.45756944 | D19: Asia/Ho_Chi_Minh | E19: S-20260924 | F19: Claude | G19: AI | H19: Huỳnh Kiện Khải | I19: CREATE | J19: P2 Định nghĩa bài toán | K19: problem_definition.md | L19: 06_reports/problem_definition.md | N19: Viết problem_definition.md theo template report_templates.md: chốt loại bài toán (hồi quy), input/output, metric chính (RMSLE) + phụ (MAE, R²), tiêu chí thành công, ràng buộc phần cứng, rủi ro và giả định. Tổng hợp lại từ các DECISION đã ghi ở P0 (LOG-0003, LOG-0004, LOG-0005) và các FINDING ở P1 (FND-0001) và P3 (FND-0002). | O19: Theo đúng thứ tự P0-P9 của skill: P2 phải chốt bằng văn bản trước khi có bất kỳ số liệu mô hình nào | R19: Info | S19: Done
A20: LOG-0019 | B20: 46289 | C20: 0.45756944 | D20: Asia/Ho_Chi_Minh | E20: S-20260924 | F20: Claude | G20: AI | H20: Huỳnh Kiện Khải | I20: NOTE | J20: P2 Định nghĩa bài toán | N20: Đính chính đánh số bước: dòng LOG-0016/LOG-0017 (chạy make_splits.py, copy script) được ghi với step-label 'P2 Chia train/val/test' do đánh số nhầm; đúng theo quy trình skill thì bước chia dữ liệu là P3, không phải P2. Không sửa lại các dòng cũ đó (append-only), chỉ đính chính tại đây. | R20: Info | S20: Done
A21: LOG-0020 | B21: 46289 | C21: 0.68884259 | D21: Asia/Ho_Chi_Minh | E21: S-20260924 | F21: Claude | G21: AI | H21: Huỳnh Kiện Khải | I21: RUN | J21: P2.5 Khám phá dữ liệu (EDA, chỉ trên train) | N21: Chạy EDA chỉ trên split=='train' của 01_data/splits/split_v1.csv (1022 dòng), tuân thủ nguyên tắc 'EDA chỉ trên train' của skill. Xem: phân phối SalePrice, missing (đối chiếu số liệu với audit toàn bộ), tương quan numeric, quét ngoại lai IQR, mức hạng mục hiếm. | R21: Info | S21: Done | X21: SalePrice train: skew=1.73 (log1p skew=0.15, xác nhận log-transform hợp lý). Missing top: PoolQC 99.4%, MiscFeature 96.0%, Alley 93.4%, Fence 80.2%, MasVnrType 59.2%, FireplaceQu 47.1% - khớp tỉ lệ với audit toàn bộ (P1), xác nhận split không lệch phân bố missing. Top tương quan: OverallQual 0.79, GrLivArea 0.69, GarageCars 0.64. 31 cột categorical có ít nhất 1 mức hiếm (<10 mẫu).
A22: LOG-0021 | B22: 46289 | C22: 0.68885417 | D22: Asia/Ho_Chi_Minh | E22: S-20260924 | F22: Claude | G22: AI | H22: Huỳnh Kiện Khải | I22: DECISION | J22: P2.5 Khám phá dữ liệu (EDA, chỉ trên train) | N22: Loại 2 dòng Id=524 và Id=1299 khỏi tập train khi fit mô hình ở P4/P5 (ngoại lai đã biết của dataset, xem FND-0003). Cách điền missing cho nhóm cột 'missing có ý nghĩa' (PoolQC, MiscFeature, Alley, Fence, MasVnrType, FireplaceQu, Garage*, Bsmt*): dùng hằng số 'None' (categorical) hoặc 0 (numeric liên quan), tính từ quyết định FND-0001 - nay xác nhận lại bằng số liệu train thực tế (tỉ lệ khớp audit toàn bộ). | O22: Kết luận rút ra từ EDA trên train, theo nguyên tắc chỉ quyết định dựa vào train | R22: Info | S22: Done | U22: FND-0003,FND-0001
A23: LOG-0022 | B23: 46289 | C23: 0.68907407 | D23: Asia/Ho_Chi_Minh | E23: S-20260924 | F23: Claude | G23: AI | H23: Huỳnh Kiện Khải | I23: CREATE | J23: P2.5 Khám phá dữ liệu (EDA, chỉ trên train) | K23: eda_train_summary.md | L23: 06_reports/eda_train_summary.md | N23: Tóm tắt EDA trên train + các quyết định rút ra, kèm tham chiếu log | R23: Info | S23: Done
A24: LOG-0023 | B24: 46289 | C24: 0.68907407 | D24: Asia/Ho_Chi_Minh | E24: S-20260924 | F24: Claude | G24: AI | H24: Huỳnh Kiện Khải | I24: CREATE | J24: P2.5 Khám phá dữ liệu (EDA, chỉ trên train) | K24: eda_train.py | L24: 03_src/scripts/eda_train.py | N24: Script EDA (chỉ đọc split=='train'), có thể chạy lại độc lập | R24: Info | S24: Done
A25: LOG-0024 | B25: 46289 | C25: 0.69363426 | D25: Asia/Ho_Chi_Minh | E25: S-20260924 | F25: Claude | G25: AI | H25: Huỳnh Kiện Khải | I25: VERIFY | J25: P1 Kiểm toán dữ liệu (bổ sung) | N25: Xem tận mắt 20 dòng ngẫu nhiên trong train (seed=7) theo yêu cầu cổng G1, kiểm tra quan hệ giữa OverallQual/GrLivArea/YearBuilt/GarageCars/SaleCondition với SalePrice. | R25: Info | S25: Done | X25: Không phát hiện nhãn bất thường/vô lý: giá tăng hợp lý theo chất lượng, diện tích, năm xây; các dòng SaleCondition='Partial'/'Family' vẫn có giá hợp lý (ngoại trừ 2 điểm đã ghi ở FND-0003, không nằm trong mẫu 20 dòng này). Gate G1 coi như đã đóng đầy đủ (đã có: manifest, missing, trùng lặp ở P1 + xem mẫu bằng mắt ở đây).
A26: LOG-0025 | B26: 46289 | C26: 0.96921296 | D26: Asia/Ho_Chi_Minh | E26: S-20260924 | F26: Claude | G26: AI | H26: Huỳnh Kiện Khải | I26: NOTE | J26: Cập nhật skill | N26: Người dùng cung cấp bản skill dl-project-from-raw-data mới (file .skill upload). Đã thay thế toàn bộ /mnt/skills/plugins/dl-project-from-raw-data bằng bản mới. Thay đổi cốt lõi: quy trình mở rộng từ P0-P9 thành P0-P11, thêm bước P4 'Khám phá dữ liệu (EDA, chỉ trên train)' chính thức (trước đây mình tự đặt tạm là 'P2.5'), và đảo thứ tự: P5 Tiền xử lý giờ đứng TRƯỚC P6 Baseline (trước đây baseline P4 đứng trước tiền xử lý P5). Số hiệu cổng G3(Baseline)/G4(pipeline) giữ nguyên tên nhưng gắn với P6/P7 mới. Đã re-áp dụng lại 2 chỉnh sửa riêng của dự án này (quy ước ghi log tiếng Việt có dấu ở SKILL.md muc 7, log_schema.md, và scripts/log_change.py README_ROWS) vì bản mới người dùng cung cấp không có 2 chỉnh sửa này. | O26: Người dùng yêu cầu cập nhật và ghi nhớ skill mới | R26: Info | S26: Done
A27: LOG-0026 | B27: 46289 | C27: 0.96921296 | D27: Asia/Ho_Chi_Minh | E27: S-20260924 | F27: Claude | G27: AI | H27: Huỳnh Kiện Khải | I27: NOTE | J27: Cập nhật skill | N27: Đối chiếu lại tiến độ dự án theo số P mới: P0 Khởi tạo=Done, P1 Kiểm toán=Done, P2 Định nghĩa bài toán=Done, P3 Chia dữ liệu=Done, P4 Khám phá dữ liệu (train)=Done (thực hiện ở các dòng LOG-0020,LOG-0021,FND-0003, lúc đó gắn nhầm nhãn 'P2.5'). Bước tiếp theo chính xác theo skill mới là P5 (Tiền xử lý: dùng scripts/preprocess_tabular.py fit/check), SAU ĐÓ mới tới P6 (Baseline) - đảo lại thứ tự so với thông báo trước đó của mình (đã nói nhầm là 'P4 Baseline' sẽ làm tiếp, nay đính chính lại). | O27: Đính chính theo cấu trúc mới của skill, không sửa các dòng log cũ | R27: Info | S27: Done
A28: LOG-0027 | B28: 46290 | C28: 0.58055556 | D28: Asia/Ho_Chi_Minh | E28: S-20260925 | F28: Claude | G28: AI | H28: Huỳnh Kiện Khải | I28: NOTE | J28: Cập nhật skill (lần 2) | N28: Người dùng upload lại file skill (cùng tên nhưng nội dung mới hơn bản đã cập nhật trước đó ở LOG-0025/0026). Điểm mới quan trọng: (1) Thêm script scripts/explore_tabular.py chuyên dụng cho P4 - tự tính thang đo, thống kê mô tả, ngoại lai IQR, giá trị ngoài miền hợp lệ, độ lệch phân phối, tương quan, độ liên quan với nhãn (Pearson/ANOVA), tự vẽ biểu đồ vào eda_plots/. (2) scripts/preprocess_tabular.py mở rộng thêm tùy chọn: --valid-range, --drop-missing-thresh, --select-anova-thresh/--select-corr-thresh (chọn đặc trưng), --bin (rời rạc hóa), --pca (giảm chiều). Đã thay thế toàn bộ thư mục skill và re-áp lại 2 chỉnh sửa riêng của dự án (quy ước log tiếng Việt có dấu ở SKILL.md, log_schema.md, log_change.py README_ROWS). | O28: Người dùng yêu cầu cập nhật bộ nhớ bằng file skill mới | R28: Info | S28: Done
A29: LOG-0028 | B29: 46290 | C29: 0.58055556 | D29: Asia/Ho_Chi_Minh | E29: S-20260925 | F29: Claude | G29: AI | H29: Huỳnh Kiện Khải | I29: NOTE | J29: Cập nhật skill (lần 2) | N29: P4 (khám phá dữ liệu) của dự án này đã hoàn thành thủ công trước khi có script explore_tabular.py, kết quả và các DECISION (LOG-0020, LOG-0021, FND-0003) vẫn giữ nguyên giá trị, không cần chạy lại. Ở bước P5 (Tiền xử lý) sắp tới, sẽ tận dụng preprocess_tabular.py bản mới, đặc biệt --valid-range cho các cột có miền giá trị rõ ràng (vd YearBuilt, GarageYrBlt không được lớn hơn năm hiện tại) nếu phù hợp. | R29: Info | S29: Done
A30: LOG-0029 | B30: 46290 | C30: 0.59855324 | D30: Asia/Ho_Chi_Minh | E30: S-20260925 | F30: Claude | G30: AI | H30: Huỳnh Kiện Khải | I30: CREATE | J30: P4 Khám phá dữ liệu (EDA) | K30: split_v1_selected_features.csv | L30: 01_data/splits/split_v1_selected_features.csv | N30: Tạo bảng con chỉ gồm 67 đặc trưng người dùng chọn lọc theo 9 nhóm ý nghĩa nghiệp vụ (khu đất, vị trí, chất lượng nhà, móng/tầng hầm, hệ thống, diện tích, garage, đường vào, giao dịch) + Id, SalePrice, split. Loại 12 cột: Fireplaces, FireplaceQu, WoodDeckSF, OpenPorchSF, EnclosedPorch, 3SsnPorch, ScreenPorch, PoolArea, PoolQC, Fence, MiscFeature, MiscVal. | R30: Info | S30: Done
A31: LOG-0030 | B31: 46290 | C31: 0.59856481 | D31: Asia/Ho_Chi_Minh | E31: S-20260925 | F31: Claude | G31: AI | H31: Huỳnh Kiện Khải | I31: RUN | J31: P4 Khám phá dữ liệu (EDA) | N31: Chạy scripts/explore_tabular.py trên split_v1_selected_features.csv (chỉ train, 1022 dòng, 67 đặc trưng), --label-col SalePrice --label-type numeric --ordinal-cols (17 cột chất lượng/thứ bậc), --valid-range cho LotFrontage/MasVnrArea/GarageYrBlt. | R31: Info | S31: Done | X31: 28 cột số, 39 cột hạng mục. 0 giá trị ngoài miền hợp lệ. Ngoại lai IQR đáng chú ý: OverallCond 8.41%, MSSubClass 7.24%, LotFrontage 6.95%, MasVnrArea 6.7%, BsmtFinSF2 9.98% (nhưng phần lớn do phân phối lệch/rời rạc, không hẳn là lỗi). Top Pearson-vs-label (numeric, chưa log-transform): OverallQual 0.786, GrLivArea 0.689, TotalBsmtSF 0.592, GarageCars 0.642, GarageArea 0.618, 1stFlrSF 0.583. Heatmap xác nhận 3 cụm cộng tuyến: (GrLivArea, FullBath, TotRmsAbvGrd, 2ndFlrSF), (GarageCars, GarageArea), (TotalBsmtSF, BsmtUnfSF, BsmtFinSF1, 1stFlrSF).
A32: LOG-0031 | B32: 46290 | C32: 0.60289352 | D32: Asia/Ho_Chi_Minh | E32: S-20260925 | F32: Claude | G32: AI | H32: Huỳnh Kiện Khải | I32: CREATE | J32: P4 Khám phá dữ liệu (EDA) | N32: Vẽ 9 biểu đồ tổng hợp theo nhóm ý nghĩa nghiệp vụ (N1_KhuDat...N9_GiaoDich), mỗi ô con là scatter(numeric vs SalePrice, có hệ số Pearson) hoặc boxplot(SalePrice theo từng mức categorical, sắp theo median tăng dần). Lưu tại 06_reports/eda/eda_plots/by_group/. | R32: Info | S32: Done
A33: LOG-0032 | B33: 46290 | C33: 0.60295139 | D33: Asia/Ho_Chi_Minh | E33: S-20260925 | F33: Claude | G33: AI | H33: Huỳnh Kiện Khải | I33: CREATE | J33: P4 Khám phá dữ liệu (EDA) | K33: eda_group_plots.py | L33: 03_src/scripts/eda_group_plots.py | N33: Script tự viết (bổ sung ngoài skill) để vẽ 9 biểu đồ theo nhóm | R33: Info | S33: Done
A34: LOG-0033 | B34: 46290 | C34: 0.6181713 | D34: Asia/Ho_Chi_Minh | E34: S-20260925 | F34: Claude | G34: AI | H34: Huỳnh Kiện Khải | I34: RUN | J34: P4 Khám phá dữ liệu (EDA) | N34: Theo đề xuất người dùng, chạy explore_tabular.py trên TOÀN BỘ 79 cột gốc (01_data/splits/split_v1.csv, chỉ train) thay vì chỉ 67 cột đã chọn, để đối chiếu ngược và tránh bỏ sót đặc trưng quan trọng. | R34: Info | S34: Done | X34: Kết quả 67 cột đã chọn khớp 100% với lần chạy trước. Phát hiện quan trọng ở nhóm 12 cột đã loại: Fireplaces (corr=0.46) và FireplaceQu (eta2=0.302) có tín hiệu MẠNH - cao hơn nhiều cột đang được giữ (vd BldgType eta2=0.048, Electrical eta2=0.079). WoodDeckSF (0.328) và OpenPorchSF (0.315) cũng ở mức trung bình-khá, tương đương HalfBath (0.278) đang được giữ. Ngược lại EnclosedPorch (-0.146), 3SsnPorch (0.062), ScreenPorch (0.143), PoolArea (0.127), MiscVal (-0.015), PoolQC (eta2=0.013), Fence (eta2=0.04), MiscFeature (eta2=0.009) đều xác nhận yếu, loại là hợp lý.
A35: LOG-0034 | B35: 46290 | C35: 0.61965278 | D35: Asia/Ho_Chi_Minh | E35: S-20260925 | F35: Claude | G35: AI | H35: Huỳnh Kiện Khải | I35: DECISION | J35: P4 Khám phá dữ liệu (EDA) | N35: Chốt danh sách đặc trưng cuối cùng: 67 cột ban đầu + 4 cột thêm lại (Fireplaces, FireplaceQu vào nhóm 3 - Chất lượng nhà; WoodDeckSF, OpenPorchSF vào nhóm 6 - Diện tích sinh hoạt) = 71 cột. Loại hẳn 8 cột còn lại (EnclosedPorch, 3SsnPorch, ScreenPorch, PoolArea, PoolQC, Fence, MiscFeature, MiscVal) do tín hiệu quá yếu (xem FND-0004). | O35: Người dùng đồng ý sau khi xem bằng chứng đối chiếu EDA toàn bộ 79 cột | R35: Info | S35: Done | U35: FND-0004
A36: LOG-0035 | B36: 46290 | C36: 0.78525463 | D36: Asia/Ho_Chi_Minh | E36: S-20260925 | F36: Claude | G36: AI | H36: Huỳnh Kiện Khải | I36: MODIFY | J36: P4 Khám phá dữ liệu (EDA) | K36: split_v1_selected_features.csv | L36: 01_data/splits/split_v1_selected_features.csv | N36: Cập nhật bảng đặc trưng đã chọn từ 67 lên 71 cột: thêm Fireplaces, FireplaceQu (nhóm 3), WoodDeckSF, OpenPorchSF (nhóm 6) theo DECISION LOG-0034. | R36: Info | S36: Done
A37: LOG-0036 | B37: 46290 | C37: 0.78525463 | D37: Asia/Ho_Chi_Minh | E37: S-20260925 | F37: Claude | G37: AI | H37: Huỳnh Kiện Khải | I37: RUN | J37: P4 Khám phá dữ liệu (EDA) | N37: Chạy lại explore_tabular.py và vẽ lại 2 biểu đồ nhóm (N3, N6) trên bảng 71 cột đã cập nhật. | R37: Info | S37: Done | X37: FireplaceQu cho bậc thang tăng dần rõ theo chất lượng (Po den Ex). WoodDeckSF/OpenPorchSF phân tán nhưng có xu hướng dương rõ. Xác nhận quyết định thêm lại là hợp lý.
A38: LOG-0037 | B38: 46290 | C38: 0.78899306 | D38: Asia/Ho_Chi_Minh | E38: S-20260925 | F38: Claude | G38: AI | H38: Huỳnh Kiện Khải | I38: CREATE | J38: P4 Khám phá dữ liệu (EDA) | K38: explore_tabular.py | L38: 03_src/scripts/explore_tabular.py | N38: Copy script explore_tabular.py (từ skill) vào dự án để chạy lại được độc lập, dùng cho cả 06_reports/eda và 06_reports/eda_full | R38: Info | S38: Done
A39: LOG-0038 | B39: 46290 | C39: 0.79274306 | D39: Asia/Ho_Chi_Minh | E39: S-20260925 | F39: Claude | G39: AI | H39: Huỳnh Kiện Khải | I39: CREATE | J39: P4 Khám phá dữ liệu (EDA) | K39: select_features.py | L39: 03_src/scripts/select_features.py | N39: Lưu code lọc 71 đặc trưng đã chọn (trước đó chỉ chạy tay, chưa lưu file) thành script chạy lại được: đọc 01_data/splits/split_v1.csv, xuất 01_data/splits/split_v1_selected_features.csv. | R39: Info | S39: Done | T39: Chạy lại, so sánh SHA256/MD5 với file hiện có: khớp 100% (6143aaca63ab186570c0c59c30c76f96).
A40: LOG-0039 | B40: 46291 | C40: 0.39013889 | D40: Asia/Ho_Chi_Minh | E40: S-20260926 | F40: Claude | G40: AI | H40: Huỳnh Kiện Khải | I40: CREATE | J40: P5 Tiền xử lý | K40: encode_business_rules.py | L40: 03_src/scripts/encode_business_rules.py | N40: Script áp quy tắc nghiệp vụ cố định (không học từ dữ liệu, áp đồng nhất train/val/test): mã hóa Ordinal cho 18 cột chất lượng/thứ bậc theo đúng thứ tự (NA=hạng 0 cho cột có thể 'không có đặc điểm'); điền 0 cho MasVnrArea, GarageYrBlt khi thiếu (missing có ý nghĩa, FND-0001); loại 2 dòng ngoại lai Id=524,1299 (FND-0003). | R40: Info | S40: Done
...

Sheet Findings
A1: Finding_ID | B1: Ngày | C1: Mức_độ | D1: Nhóm | E1: Bước_pipeline | F1: Tên_file | G1: Vị_trí | H1: Mô_tả | I1: Bằng_chứng | J1: Cách_sửa_đề_xuất | K1: Trạng_thái | L1: Log_ID_liên_quan
A2: FND-0001 | B2: 46288 | C2: Medium | D2: Missing data | E2: P1 Kiểm toán dữ liệu | F2: 00_raw/train.csv | H2: 19 cột có giá trị thiếu. Đã đối chiếu với data_description của dataset Ames Housing: hầu hết là 'missing có ý nghĩa' (nhà không có đặc điểm đó), VD PoolQC/Fence/Alley/MiscFeature/FireplaceQu/Garage*/Bsmt* thiếu vì nhà không có hồ bơi/hàng rào/garage/tầng hầm. | I2: 01_data/audit/data_report.md; PoolQC thiếu 1453/1460 (99.5%), MiscFeature 1406 (96.3%), Alley 1369 (93.8%) | J2: P3 sẽ impute các cột này bằng giá trị hằng số 'None' (categorical) hoặc 0 (numeric liên quan tới đặc điểm không tồn tại, VD MasVnrArea), KHÔNG dùng median/mode mặc định cho nhóm này. [Đã áp dụng ở P5 - encode_business_rules.py, LOG-0039] | K2: Done
A3: FND-0002 | B3: 46289 | C3: Low | D3: Chia dữ liệu | E3: P2 Chia train/val/test | F3: 01_data/splits/split_v1_summary.json | H3: Trường 'strategy' trong summary.json ghi 'stratified' dù thực tế script đã cảnh báo và chuyển sang chia ngẫu nhiên (fallback) vì SalePrice là hồi quy liên tục, không phải nhãn phân loại. Đây là hạn chế hiển thị của script make_splits.py (thiết kế chính cho bài toán phân loại), không phải lỗi của kết quả chia. | I3: Log console: 'CANH BAO: stratify that bai ... dung chia ngau nhien' | J3: Không cần sửa vì với hồi quy, chia ngẫu nhiên (có seed cố định) là hợp lý; chỉ cần ghi chú lại để không hiểu nhầm là đã stratify theo khoảng giá. | K3: Wontfix
A4: FND-0003 | B4: 46289 | C4: High | D4: Ngoại lai / lỗi dữ liệu | E4: P2.5 Khám phá dữ liệu (EDA, chỉ trên train) | F4: 01_data/splits/split_v1.csv | G4: Id=524, Id=1299 | H4: 2 căn nhà có GrLivArea rất lớn (4676 và 5642 sqft) và OverallQual=10 nhưng SalePrice lại RẤT THẤP (184750 và 160000) - thấp hơn nhiều nhà nhỏ hơn nhiều. Cả 2 đều có SaleCondition='Partial' (nhà bán khi CHƯA hoàn thiện/xây xong). Đây là lỗi/ngoại lai đã được chính tác giả dataset (Dean De Cock) ghi nhận công khai, khuyến nghị loại khỏi tập train. Có 1 điểm thứ 3 (Id=1183, GrLivArea=4476, SalePrice=745000, SaleCondition='Abnorml') là giá cao nhất trong toàn bộ dữ liệu - đây là điểm HỢP LỆ (không phải lỗi), không loại. | I4: 02_notebooks/eda_train.png (scatter GrLivArea vs SalePrice); bảng chi tiết 3 dòng GrLivArea>4000 trong train | J4: DECISION: loại 2 dòng Id=524 và Id=1299 khỏi TRAIN khi huấn luyện baseline/mô hình (P4/P5). KHÔNG loại khỏi val/test (val/test không có 2 Id này vì đều rơi vào train ở split_v1, nhưng nguyên tắc chung: ngoại lai chỉ loại ở train). Giữ nguyên Id=1183 vì là giá trị hợp lệ, không phải lỗi. [Đã áp dụng ở P5 - encode_business_rules.py, LOG-0039] | K4: Done
A5: FND-0004 | B5: 46290 | C5: Medium | D5: Chọn đặc trưng | E5: P4 Khám phá dữ liệu (EDA) | F5: 06_reports/eda_full/eda_report.md | H5: Trong 12 cột người dùng loại ban đầu (nhóm 'extras'), 3-4 cột thực ra có tín hiệu đáng kể với SalePrice: Fireplaces (corr=0.46), FireplaceQu (eta2=0.302), WoodDeckSF (corr=0.328), OpenPorchSF (corr=0.315). Đây là bằng chứng số liệu (chỉ từ train) nên cân nhắc thêm lại các cột này. | I5: 06_reports/eda_full/eda_report.md, mục 'Độ liên quan với biến mục tiêu' | J5: Đề xuất: thêm Fireplaces + FireplaceQu (nhóm 3 Chất lượng nhà) và WoodDeckSF + OpenPorchSF (nhóm 6 Diện tích) vào danh sách giữ lại; giữ nguyên loại 8 cột còn lại (EnclosedPorch, 3SsnPorch, ScreenPorch, PoolArea, PoolQC, Fence, MiscFeature, MiscVal). [Đã thực hiện - xem LOG-0034] | K5: Done
A6: FND-0005 | B6: 46290 | C6: Medium | D6: Chọn đặc trưng | E6: P4 Khám phá dữ liệu (EDA) | F6: 06_reports/eda_full/eda_report.md | H6: Trong 12 cột người dùng loại ban đầu (nhóm 'extras'), 3-4 cột thực ra có tín hiệu đáng kể với SalePrice: Fireplaces (corr=0.46), FireplaceQu (eta2=0.302), WoodDeckSF (corr=0.328), OpenPorchSF (corr=0.315). Đây là bằng chứng số liệu (chỉ từ train) nên cân nhắc thêm lại các cột này. | I6: 06_reports/eda_full/eda_report.md, mục 'Độ liên quan với biến mục tiêu' | J6: Đã thêm lại 4 cột này vào danh sách giữ (xem LOG tiếp theo). | K6: Done
A7: FND-0006 | B7: 46291 | C7: Medium | D7: Phân tích lỗi | E7: P9 Đánh giá cuối | F7: 05_experiments/exp0004_val_predictions.csv | H7: Phân tích lỗi trên VAL (không dùng test): 6/10 dòng có sai số tuyệt đối lớn nhất đều có SaleCondition khác 'Normal' (Abnorml: bán gấp/khó khăn tài chính; Partial: nhà mới xây bán trực tiếp). Case cực đoan: Id=496, SalePrice=$34,900 (rẻ nhất toàn dataset, SaleCondition=Abnorml, chỉ 720 sqft) bị dự đoán lệch 131%. | I7: 05_experiments/exp0004_val_predictions.csv, đối chiếu Neighborhood/OverallQual/SaleCondition | J7: Hướng cải thiện tiềm năng cho vòng thí nghiệm sau: thêm interaction feature giữa SaleCondition và các đặc trưng chính, hoặc huấn luyện mô hình riêng/điều chỉnh cho phân khúc SaleCondition != Normal. Không sửa ngay vì test đã đóng, đây chỉ là ghi nhận cho báo cáo cuối. | K7: Open

Sheet File_Registry
A1: Đường_dẫn | B1: Loại | C1: Kích_thước_byte | D1: SHA256 | E1: Vai_trò | F1: Ngày_đăng_ký | G1: Log_ID_đăng_ký
A2: 00_raw/train.csv | B2: csv | C2: 460676 | D2: 1e18addf81e5e4d347cc17ee6075bbe4a42b7fa26b9e5b063e8f692a5f929d41 | E2: raw dataset (Ames Housing, Kaggle House Prices) | F2: 46287
A3: requirements.txt | B3: txt | C3: 365 | D3: 1529842f18f3fc9ddc13f8a29f9fea308b93c99ae341d224cb35f419f9b5ba4c | E3: pinned deps for ML pipeline | F3: 46287
A4: setup_env.sh | B4: sh | C4: 415 | D4: 0ec14ff51fe75452e37d68a2f7f5d6b9b310104f03c4c73bddc63947f123317d | E4: venv setup script (Linux/macOS) | F4: 46287
A5: setup_env.bat | B5: bat | C5: 420 | D5: 6a3e68f17fb0c3ee20f0bf5c49390905563b41f881ed652f9db93ac322d5fbf2 | E5: venv setup script (Windows) | F5: 46287
A6: 01_data/audit/manifest.csv | B6: csv | C6: 192 | D6: 0661f403d0fa6217d8fa3cb3e36863a973ee618dd8ba55c72c1f639c7b859efa | E6: audit manifest | F6: 46288
A7: 01_data/audit/audit.json | B7: json | C7: 22802 | D7: 7875412bf87b767417431ff68b3b1c458b7dd8265b0967eeb4e0dc0b2eeb8f1f | E7: audit metrics (machine-readable) + dataset fingerprint | F7: 46288
A8: 01_data/audit/data_report.md | B8: md | C8: 9524 | D8: 300a7b77f9a00aaeabe1c47b6a77c50f58c9f41bd879a1c9171af8b99d5d174e | E8: audit report (Vietnamese) | F8: 46288
A9: 03_src/scripts/audit_dataset.py | B9: py | C9: 13590 | D9: 651e87e1e34d9b889dcf31bbb469577af64f919349a92be19a763f8db2889268 | E9: script kiem toan du lieu (P1) | F9: 46288
A10: 01_data/splits/split_v1.csv | B10: csv | C10: 468785 | D10: a7efd8bd0070df62801eafc5d8e213858f8ca7d8851dafd4d7115d480b886448 | E10: bảng đã gán cột split (train/val/test) | F10: 46289
A11: 01_data/splits/split_v1_summary.json | B11: json | C11: 48765 | D11: 4e71c3bc4a19ceee2c9bc213bc10aaa7b5c652b8fa88962dd5a37090f0f128d4 | E11: thống kê + fingerprint của lần chia split v1 | F11: 46289
A12: 03_src/scripts/make_splits.py | B12: py | C12: 9337 | D12: eed3ee2f3aa1f8def8944cade841ad0f0a65603832f2ce3a3bcf3410f60da9b7 | E12: script chia train/val/test (P2) | F12: 46289
A13: 06_reports/problem_definition.md | B13: md | C13: 2868 | D13: 61a88c960eeb23174f2879c0d3d7bfbc1c25cb58cd6371753c4fde22af5327aa | E13: định nghĩa bài toán, metric, ràng buộc (P2) | F13: 46289
... A80: 03_src/scripts/p10_dong_goi/make_slides.js | B80: js | C80: 16963 | D80: adde390948c167894835b27a1b588a490a2d4c24708d6d4929ebe6537ea8b93e | E80: script sinh Slide (pptxgenjs) | F80: 46292

Sheet Experiments
A1: Exp_ID | B1: Ngày | C1: Giờ | D1: Người_thực_hiện | E1: Mục_tiêu/Giả_thuyết | F1: Exp_cha | G1: Thay_đổi_so_với_exp_cha | H1: Model | I1: Số_tham_số | J1: Phiên_bản_dữ_liệu/Split | K1: Đường_dẫn_config | L1: Hash_config | M1: Seed | N1: Epochs | O1: Batch | P1: Optimizer | Q1: LR | R1: Augmentation | S1: Tên_metric | T1: Train_metric | U1: Val_metric | V1: Test_metric (chỉ mô hình cuối) | W1: Thời_gian_train | X1: Phần_cứng | Y1: Checkpoint | Z1: Kết_luận | AA1: Trạng_thái | AB1: Log_ID_liên_quan
A2: EXP-0001 | B2: 46291 | C2: 0.44508102 | D2: Claude | E2: Baseline tam thuong (G3) - moc san de so sanh moi mo hinh sau nay | H2: constant_mean | J2: split_v1_prepped (sau P5) | S2: RMSLE | U2: 0.406 | Z2: Du doan hang so = trung binh SalePrice(train)=180921. MAE=58299, R2=-0.007 (gan 0, dung nghia la khong giai thich duoc gi). Day la san duoi cung, moi mo hinh phai vuot xa con so nay. | AA2: Done
A3: EXP-0002 | B3: 46291 | C3: 0.44508102 | D3: Claude | E3: Baseline co dien (G3) - XGBoost tren 205 dac trung da tien xu ly | H3: XGBRegressor(n_estimators=500, lr=0.05, max_depth=4, subsample=0.8, colsample_bytree=0.8) | J3: split_v1_prepped (sau P5), fit tren log1p(SalePrice) | M3: 42 | S3: RMSLE | U3: 0.1267 | Z3: RMSLE=0.1267 (val), MAE=15637, R2=0.910. Vuot baseline tam thuong rat xa (RMSLE giam tu 0.406 xuong 0.127, R2 tu -0.007 len 0.910). Xac nhan huong ML (khong DL) la hop ly cho du lieu bang nay, dung theo nguyen tac 8 cua skill. | AA3: Done
A4: EXP-0003 | B4: 46291 | C4: 0.44989583 | D4: Claude | E4: Baseline bo sung theo yeu cau nguoi dung: Linear Regression de tinh tham so/he so tung dac trung | F4: EXP-0002 | H4: LinearRegression (scikit-learn, khong regularization) | J4: split_v1_prepped (sau P5), fit tren log1p(SalePrice) | S4: RMSLE | U4: 0.1143 | Z4: RMSLE=0.1143, MAE=13322, R2=0.948 - tot hon ca XGBoost baseline (EXP-0002: RMSLE=0.1267). CANH BAO khi doc he so: 15/15 he so lon nhat deu la cac cot one-hot cua muc hang muc HIEM (vd Condition2_RRAe, Exterior1st_BrkComm - chi vai mau), day la dau hieu phuong sai he so cao do qua it quan sat, KHONG phai bang chung do quan trong thuc su. Can dung Ridge/Lasso (co regularization) neu muon doc he so on dinh, dang tin cay hon. | AA4: Done
A5: EXP-0004 | B5: 46291 | C5: 0.62028935 | D5: Claude | E5: Ridge Regression (L2) de co bang he so on dinh, dang tin cay hon Linear Regression thuong (EXP-0003) | F5: EXP-0003 | H5: RidgeCV(alphas=[0.1..1000], cv=5, chon alpha bang CV tren TRAIN) | J5: split_v1_prepped (sau P5), fit tren log1p(SalePrice) | S5: RMSLE | U5: 0.1155 | V5: 0.1301 | Z5: Test RMSLE=0.1301 (MAE=$14280, R2=0.943, bootstrap 95% CI=[0.099,0.159], n=219). Mo test dung 1 lan, xem LOG-0064 (DECISION mo test) va LOG-0065 (RUN). | AA5: Done
A6: EXP-0005 | B6: 46291 | C6: 0.63140046 | D6: Claude | E6: P8, gia thuyet: tinh chinh sieu tham so XGBoost bang RandomizedSearchCV (5-fold CV tren TRAIN) se cai thien so voi XGBoost mac dinh EXP-0002 | F6: EXP-0002 | H6: XGBRegressor (best params tu RandomizedSearchCV, 60 iter): max_depth=2, n_estimators=1200, lr=0.03, subsample=0.7, colsample_bytree=1.0, reg_alpha=0.1, reg_lambda=1.5, min_child_weight=2 | J6: split_v1_prepped (sau P5) | M6: 42 | S6: RMSLE | U6: 0.1245 | Z6: Cai thien so voi XGBoost mac dinh (EXP-0002: 0.1267 -> 0.1245, giam nhe). Nhung VAN KEM HON Ridge (EXP-0004: 0.1155) va Linear Regression (EXP-0003: 0.1143). Dieu nay cung co gia thuyet: voi 205 dac trung da duoc feature-engineer tot (one-hot + ordinal), quan he voi log(SalePrice) chu yeu la TUYEN TINH, nen mo hinh tuyen tinh co regularization dang thang the hon cay quyet dinh o quy mo du lieu nho (1020 dong). Gia thuyet tiep theo dang can nhac: stacking Ridge+XGBoost, hoac feature engineering them (interaction terms). | AA6: Done

Sheet Summary
A1: Thống kê nhật ký (công thức - chạy recalc.py để cập nhật giá trị cache)
A3: Tổng số dòng log | B3: =COUNTA(Change_Log!A2:A5000) -> 76 | D3: Tổng số thí nghiệm | E3: =COUNTA(Experiments!A2:A5000) -> 5
A4: Tổng số finding | B4: =COUNTA(Findings!A2:A5000) -> 6 | D4: Thí nghiệm Done | E4: =COUNTIF(Experiments!AA2:AA5000,"Done") -> 5
A5: Finding còn Open | B5: =COUNTIF(Findings!K2:K5000,"Open") -> 1 | D5: Thí nghiệm Failed | E5: =COUNTIF(Experiments!AA2:AA5000,"Failed") -> 0
A7: Theo loại hành động
A8: EXPLORE | B8: =COUNTIF(Change_Log!I2:I5000,A8) -> 0
A9: DISCOVER | B9: =COUNTIF(Change_Log!I2:I5000,A9) -> 0
A10: CREATE | B10: =COUNTIF(Change_Log!I2:I5000,A10) -> 32
A11: MODIFY | B11: =COUNTIF(Change_Log!I2:I5000,A11) -> 13
A12: FIX | B12: =COUNTIF(Change_Log!I2:I5000,A12) -> 5
A13: DELETE | B13: =COUNTIF(Change_Log!I2:I5000,A13) -> 0
A14: RUN | B14: =COUNTIF(Change_Log!I2:I5000,A14) -> 9
A15: VERIFY | B15: =COUNTIF(Change_Log!I2:I5000,A15) -> 3
A16: DECISION | B16: =COUNTIF(Change_Log!I2:I5000,A16) -> 8
A17: NOTE | B17: =COUNTIF(Change_Log!I2:I5000,A17) -> 6
A19: Theo trạng thái
A20: Done | B20: =COUNTIF(Change_Log!S2:S5000,A20) -> 76
A21: Open | B21: =COUNTIF(Change_Log!S2:S5000,A21) -> 0
A22: Needs-confirmation | B22: =COUNTIF(Change_Log!S2:S5000,A22) -> 0
A23: Reverted | B23: =COUNTIF(Change_Log!S2:S5000,A23) -> 0
A24: Wontfix | B24: =COUNTIF(Change_Log!S2:S5000,A24) -> 0
A26: Theo mức độ
A27: Info | B27: =COUNTIF(Change_Log!R2:R5000,A27) -> 76
A28: Low | B28: =COUNTIF(Change_Log!R2:R5000,A28) -> 0
A29: Medium | B29: =COUNTIF(Change_Log!R2:R5000,A29) -> 0
A30: High | B30: =COUNTIF(Change_Log!R2:R5000,A30) -> 0
A31: Critical | B31: =COUNTIF(Change_Log!R2:R5000,A31) -> 0
